Workbook

Sheet Creatures
A3: Creature | B3: Types | C3: Base Power | D3: TMod1 | E3: mod | F3: TMod2 | G3: mod | H3: TMod3 | I3: mod | J3: TMod4 | K3: mod | L3: TMod5 | M3: mod | N3: TMod6 | O3: mod | P3: Ability 1 | Q3: Ability 2 | R3: Rest cost | S3: Point Cost
A4: Adir Doe | B4: Cervid, Plant | C4: 2 | D4: Forest | E4: 4 | F4: Plain | G4: 3 | H4: Mountain | I4: 2 | J4: Desert | K4: -2 | L4: Wasteland | M4: -3 | P4: Disguise Young | Q4: Hide Young | R4: 2 | S4: 3
A5: Adir Fawn | B5: Cervid, Plant | C5: 1 | D5: Forest | E5: 2 | F5: Plain | G5: 1 | H5: Mountain | I5: 1 | J5: Desert | K5: -3 | L5: Wasteland | M5: -4 | P5: Birth | Q5: Feed | R5: 1 | S5: 1
A6: Adir Lookout | B6: Cervid, Theraphosid | C6: 2 | D6: Forest | E6: 3 | F6: Mountain | G6: 2 | H6: Plain | I6: 1 | J6: Desert | K6: -3 | L6: Wasteland | M6: -5 | P6: Eyes Peeled | Q6: Hoof Stomp | R6: 2 | S6: 2
A7: Adir Luminantler | B7: Cervid, Plant, Light | C7: 7 | D7: Forest | E7: 7 | F7: Plain | G7: 5 | H7: Mountain | I7: 4 | J7: Desert | K7: -1 | L7: Wasteland | M7: -2 | P7: Light Tail | R7: 4 | S7: 10
A8: Adir Mossback | B8: Cervid, Plant, Poison | C8: 2 | D8: Forest | E8: 4 | F8: Plain | G8: 3 | H8: Mountain | I8: 2 | J8: Desert | K8: -2 | L8: Wasteland | M8: -5 | P8: Poison Moss | Q8: Intercept | R8: 3 | S8: 4
A9: Adir Runhart | B9: Cervid, Chiropteran | C9: 2 | D9: Mountain | E9: 5 | F9: Forest | G9: 4 | H9: Plain | I9: 3 | J9: Cloud | K9: 2 | L9: Wasteland | M9: -9 | P9: Scout | Q9: Deer Call | R9: 2 | S9: 4
A10: Adir Rutbuck | B10: Cervid, Plant | C10: 4 | D10: Forest | E10: 4 | F10: Plain | G10: 4 | H10: Mountain | I10: 4 | J10: Desert | K10: -4 | L10: Wasteland | M10: -4 | P10: Rack Attack | R10: 2 | S10: 7
A11: Adir Stag | B11: Cervid, Plant | C11: 5 | D11: Forest | E11: 5 | F11: Plain | G11: 4 | H11: Mountain | I11: 4 | J11: Desert | K11: -5 | L11: Wasteland | M11: -7 | P11: Reality Bend | R11: 3 | S11: 10
A12: Adir Yearling | B12: Cervid, Plant | C12: 3 | D12: Forest | E12: 4 | F12: Plain | G12: 3 | H12: Mountain | I12: 2 | J12: Desert | K12: -3 | L12: Wasteland | M12: -4 | P12: Antler Stab | R12: 2 | S12: 3
A13: Adir Zunderbie | B13: Cervid, Poison, Undead | C13: 1 | D13: Wasteland | E13: 2 | F13: Forest | G13: -1 | H13: Mountain | I13: -1 | J13: Plain | K13: -1 | L13: Desert | M13: -1 | P13: Wasting | Q13: Perseverance | R13: 1 | S13: 1
A14: Embird | B14: Ramphastid, Fire | C14: 3 | D14: Volcano | E14: 7 | F14: Wasteland | G14: 5 | H14: Jungle | I14: 3 | J14: Mountain | K14: -2 | L14: Tundra | M14: -7 | P14: Flame Spit | R14: 3 | S14: 5
A15: Fire Fir | B15: Plant, Fire, Rock | C15: 1 | D15: Volcano | E15: 1 | F15: Wasteland | G15: 1 | H15: Jungle | I15: 1 | J15: Cloud | K15: -3 | L15: Tundra | M15: -7 | P15: Cinder Roots | Q15: Indigenous | S15: 2
A16: Firefly | B16: Lampyrid, Fire, Light | C16: 1 | D16: Volcano | E16: 1 | F16: Mountain | G16: 1 | H16: Forest | I16: 1 | J16: Plain | K16: 1 | P16: Glow | R16: 2 | S16: 1
A17: Flaimingo | B17: Phoenicopterid, Stone | C17: 2 | D17: Volcano | E17: 5 | F17: Lake | G17: 4 | H17: Swamp | I17: 3 | J17: Mountain | K17: -4 | L17: Ocean | M17: -6 | P17: Obsidian Feet | R17: 1 | S17: 3
A18: Fyrorage | B18: Fire, Elementid | C18: 5 | D18: Volcano | E18: 10 | F18: Forest | G18: 5 | H18: Cloud | I18: -5 | J18: Lake | K18: -6 | L18: Ocean | M18: -7 | P18: Flash Fire | Q18: Homebound | R18: 1 | S18: 6
A19: Iguaneous | B19: Iguanid, Stone | C19: 3 | D19: Volcano | E19: 7 | F19: Wasteland | G19: 4 | H19: Desert | I19: 3 | J19: Cloud | K19: -2 | L19: Tundra | M19: -3 | P19: Sunbathe | R19: 2 | S19: 5
A20: Lava Grub | B20: Lumbricid, Fire | C20: 1 | D20: Volcano | E20: 2 | P20: Acclimate Volcano | R20: 1 | S20: 1
A21: Magma Drake | B21: Draconid, Fire, Stone | C21: 15 | D21: Volcano | E21: 25 | F21: Mountain | G21: 15 | H21: Wasteland | I21: 10 | J21: Jungle | K21: 7 | L21: Cloud | M21: 3 | P21: Fire Breath | R21: 7 | S21: 30
A22: Magnimog | B22: Cervid, Fire, Elementid | C22: 1 | D22: Volcano | E22: 8 | F22: Wasteland | G22: 5 | H22: Forest | I22: -1 | J22: Mountain | K22: -1 | L22: Plain | M22: -1 | P22: Consume Flesh | Q22: Consume Land | R22: 3 | S22: 8
A23: Armored Shroom | B23: Polyporiceae, Stone | C23: 1 | D23: Volcano | E23: 1 | F23: Tundra | G23: -1 | H23: Desert | I23: -1 | P23: Armor Up | S23: 2
A24: Obsidiax | B24: Scarabaeid, Stone, Elementid | C24: 2 | D24: Wasteland | E24: 5 | F24: Volcano | G24: 4 | H24: Ocean | I24: 3 | J24: Jungle | K24: -2 | L24: Plain | M24: -7 | P24: Obsidian Armor | Q24: Obsidian Ball | R24: 4 | S24: 2
A25: Phoenix Pegasus | B25: Equid, Accipitrid, Fire | C25: 3 | D25: Volcano | E25: 7 | F25: Cloud | G25: 4 | H25: Plain | I25: 3 | P25: Flamebow | Q25: Ashes | R25: 2 | S25: 9
A26: Shady Raccoon | B26: Procyonid | C26: 2 | D26: Wasteland | E26: 25 | F26: Forest | G26: 15 | H26: Lake | I26: -4 | J26: Mountain | K26: -7 | L26: Desert | M26: -15 | N26: Cloud | O26: -15 | P26: Shady Deal | R26: 1 | S26: 2
A27: Moonhowler | B27: Canid | C27: 5 | D27: Forest | E27: 10 | F27: Tundra | G27: 9 | H27: Lake | I27: 2 | J27: Plain | K27: -3 | L27: Mountain | M27: -5 | P27: Howl Call | R27: 5 | S27: 8
A28: Vire | B28: Culicid, Poison | C28: 1 | D28: Swamp | E28: 1 | F28: Lake | G28: 1 | H28: Ocean | I28: 1 | J28: Cloud | K28: 1 | L28: Wasteland | M28: 1 | P28: Swarm | Q28: Poison Bite | S28: 1
A29: Adir Elder | B29: Plant | C29: 1 | D29: Forest | E29: 15 | F29: Volcano | G29: -10 | H29: Desert | I29: -10 | J29: Tundra | K29: -10 | L29: Wasteland | M29: -10 | P29: Gather the Herd | Q29: Indigenous | R29: 2 | S29: 10

Sheet Species
A3: Name | B3: Creature Code | C3: Base Power | D3: Terrain Mods | E3: Rest | F3: Magic Genus | G3: Male Code | I3: Female Code | K3: Male Code
A4: Adir | B4: ADIR | C4: B | D4: DENCJBC9W8 | E4: A | F4: S | G4: fDIR | I4: =_xlfn.CONCAT(B4,C4,"U",D4,"U",E4,F4,B4) -> ADIRBUDENCJBC9W8UASADIR | J4: =LEN(I4) -> 23 | K4: =_xlfn.CONCAT(B4,C4,"U",D4,"U",E4,F4,G4) -> ADIRBUDENCJBC9W8UASfDIR | L4: =LEN(K4) -> 23
A5: Embird | B5: EMBIRD | C5: C | D5: TGVEFCK4S0 | E5: B | F5: j | G5: kMBIRD | I5: =_xlfn.CONCAT(B5,C5,"U",D5,"U",E5,F5,B5) -> EMBIRDCUTGVEFCK4S0UBjEMBIRD | J5: =LEN(I5) -> 27 | K5: =_xlfn.CONCAT(B5,C5,"U",D5,"U",E5,F5,G5) -> EMBIRDCUTGVEFCK4S0UBjkMBIRD | L5: =LEN(K5) -> 27

Sheet Worksheet
A3: Terrain | B3: Mod | C3: Number | D3: Num Bin | E3: Mod Bin | F3: Combined | M3: Character Code
A4: Forest | B4: 5 | C4: =IF(ISBLANK(A4),0, _xlfn.XMATCH(A4,Constants!B:B)-1) -> 2 | D4: =DEC2BIN(C4,5) -> 00010 | E4: =_xlfn.CONCAT(IF(B4>=0,"0","1"),DEC2BIN(B4,6)) -> 0000101 | F4: =_xlfn.CONCAT(D4,E4) -> 000100000101 | G4: =LEFT(F4,6) -> 000100 | H4: =RIGHT(F4,6) -> 000101 | I4: =BIN2DEC(G4) -> 4 | J4: =BIN2DEC(H4) -> 5 | K4: {=IF(I4=0,"",INDEX(Constants!$L:$L,Worksheet!I4))} -> D | L4: {=IF(J4=0,"",INDEX(Constants!$L:$L,Worksheet!J4))} -> E | M4: =_xlfn.CONCAT(K4,L4) -> DE
A5: Plain | B5: 3 | C5: =IF(ISBLANK(A5),0, _xlfn.XMATCH(A5,Constants!B:B)-1) -> 7 | D5: =DEC2BIN(C5,5) -> 00111 | E5: =_xlfn.CONCAT(IF(B5>=0,"0","1"),DEC2BIN(B5,6)) -> 0000011 | F5: =_xlfn.CONCAT(D5,E5) -> 001110000011 | G5: =LEFT(F5,6) -> 001110 | H5: =RIGHT(F5,6) -> 000011 | I5: =BIN2DEC(G5) -> 14 | J5: =BIN2DEC(H5) -> 3 | K5: {=IF(I5=0,"",INDEX(Constants!$L:$L,Worksheet!I5))} -> N | L5: {=IF(J5=0,"",INDEX(Constants!$L:$L,Worksheet!J5))} -> C | M5: =_xlfn.CONCAT(K5,L5) -> NC
A6: Mountain | B6: 2 | C6: =IF(ISBLANK(A6),0, _xlfn.XMATCH(A6,Constants!B:B)-1) -> 5 | D6: =DEC2BIN(C6,5) -> 00101 | E6: =_xlfn.CONCAT(IF(B6>=0,"0","1"),DEC2BIN(B6,6)) -> 0000010 | F6: =_xlfn.CONCAT(D6,E6) -> 001010000010 | G6: =LEFT(F6,6) -> 001010 | H6: =RIGHT(F6,6) -> 000010 | I6: =BIN2DEC(G6) -> 10 | J6: =BIN2DEC(H6) -> 2 | K6: {=IF(I6=0,"",INDEX(Constants!$L:$L,Worksheet!I6))} -> J | L6: {=IF(J6=0,"",INDEX(Constants!$L:$L,Worksheet!J6))} -> B | M6: =_xlfn.CONCAT(K6,L6) -> JB
A7: Desert | B7: -2 | C7: =IF(ISBLANK(A7),0, _xlfn.XMATCH(A7,Constants!B:B)-1) -> 1 | D7: =DEC2BIN(C7,5) -> 00001 | E7: =_xlfn.CONCAT(IF(B7>=0,"0","1"),DEC2BIN(B7,6)) -> 11111111110 | F7: =_xlfn.CONCAT(D7,E7) -> 0000111111111110 | G7: =LEFT(F7,6) -> 000011 | H7: =RIGHT(F7,6) -> 111110 | I7: =BIN2DEC(G7) -> 3 | J7: =BIN2DEC(H7) -> 62 | K7: {=IF(I7=0,"",INDEX(Constants!$L:$L,Worksheet!I7))} -> C | L7: {=IF(J7=0,"",INDEX(Constants!$L:$L,Worksheet!J7))} -> 9 | M7: =_xlfn.CONCAT(K7,L7) -> C9
A8: Wasteland | B8: -3 | C8: =IF(ISBLANK(A8),0, _xlfn.XMATCH(A8,Constants!B:B)-1) -> 11 | D8: =DEC2BIN(C8,5) -> 01011 | E8: =_xlfn.CONCAT(IF(B8>=0,"0","1"),DEC2BIN(B8,6)) -> 11111111101 | F8: =_xlfn.CONCAT(D8,E8) -> 0101111111111101 | G8: =LEFT(F8,6) -> 010111 | H8: =RIGHT(F8,6) -> 111101 | I8: =BIN2DEC(G8) -> 23 | J8: =BIN2DEC(H8) -> 61 | K8: {=IF(I8=0,"",INDEX(Constants!$L:$L,Worksheet!I8))} -> W | L8: {=IF(J8=0,"",INDEX(Constants!$L:$L,Worksheet!J8))} -> 8 | M8: =_xlfn.CONCAT(K8,L8) -> W8
A9: Volcano | B9: 7 | C9: =IF(ISBLANK(A9),0, _xlfn.XMATCH(A9,Constants!B:B)-1) -> 10 | D9: =DEC2BIN(C9,5) -> 01010 | E9: =_xlfn.CONCAT(IF(B9>=0,"0","1"),DEC2BIN(B9,6)) -> 0000111 | F9: =_xlfn.CONCAT(D9,E9) -> 010100000111 | G9: =LEFT(F9,6) -> 010100 | H9: =RIGHT(F9,6) -> 000111 | I9: =BIN2DEC(G9) -> 20 | J9: =BIN2DEC(H9) -> 7 | K9: {=IF(I9=0,"",INDEX(Constants!$L:$L,Worksheet!I9))} -> T | L9: {=IF(J9=0,"",INDEX(Constants!$L:$L,Worksheet!J9))} -> G | M9: =_xlfn.CONCAT(K9,L9) -> TG
A10: Wasteland | B10: 5 | C10: =IF(ISBLANK(A10),0, _xlfn.XMATCH(A10,Constants!B:B)-1) -> 11 | D10: =DEC2BIN(C10,5) -> 01011 | E10: =_xlfn.CONCAT(IF(B10>=0,"0","1"),DEC2BIN(B10,6)) -> 0000101 | F10: =_xlfn.CONCAT(D10,E10) -> 010110000101 | G10: =LEFT(F10,6) -> 010110 | H10: =RIGHT(F10,6) -> 000101 | I10: =BIN2DEC(G10) -> 22 | J10: =BIN2DEC(H10) -> 5 | K10: {=IF(I10=0,"",INDEX(Constants!$L:$L,Worksheet!I10))} -> V | L10: {=IF(J10=0,"",INDEX(Constants!$L:$L,Worksheet!J10))} -> E | M10: =_xlfn.CONCAT(K10,L10) -> VE
A11: Jungle | B11: 3 | C11: =IF(ISBLANK(A11),0, _xlfn.XMATCH(A11,Constants!B:B)-1) -> 3 | D11: =DEC2BIN(C11,5) -> 00011 | E11: =_xlfn.CONCAT(IF(B11>=0,"0","1"),DEC2BIN(B11,6)) -> 0000011 | F11: =_xlfn.CONCAT(D11,E11) -> 000110000011 | G11: =LEFT(F11,6) -> 000110 | H11: =RIGHT(F11,6) -> 000011 | I11: =BIN2DEC(G11) -> 6 | J11: =BIN2DEC(H11) -> 3 | K11: {=IF(I11=0,"",INDEX(Constants!$L:$L,Worksheet!I11))} -> F | L11: {=IF(J11=0,"",INDEX(Constants!$L:$L,Worksheet!J11))} -> C | M11: =_xlfn.CONCAT(K11,L11) -> FC
A12: Mountain | B12: -7 | C12: =IF(ISBLANK(A12),0, _xlfn.XMATCH(A12,Constants!B:B)-1) -> 5 | D12: =DEC2BIN(C12,5) -> 00101 | E12: =_xlfn.CONCAT(IF(B12>=0,"0","1"),DEC2BIN(B12,6)) -> 11111111001 | F12: =_xlfn.CONCAT(D12,E12) -> 0010111111111001 | G12: =LEFT(F12,6) -> 001011 | H12: =RIGHT(F12,6) -> 111001 | I12: =BIN2DEC(G12) -> 11 | J12: =BIN2DEC(H12) -> 57 | K12: {=IF(I12=0,"",INDEX(Constants!$L:$L,Worksheet!I12))} -> K | L12: {=IF(J12=0,"",INDEX(Constants!$L:$L,Worksheet!J12))} -> 4 | M12: =_xlfn.CONCAT(K12,L12) -> K4
A13: Tundra | B13: -11 | C13: =IF(ISBLANK(A13),0, _xlfn.XMATCH(A13,Constants!B:B)-1) -> 9 | D13: =DEC2BIN(C13,5) -> 01001 | E13: =_xlfn.CONCAT(IF(B13>=0,"0","1"),DEC2BIN(B13,6)) -> 11111110101 | F13: =_xlfn.CONCAT(D13,E13) -> 0100111111110101 | G13: =LEFT(F13,6) -> 010011 | H13: =RIGHT(F13,6) -> 110101 | I13: =BIN2DEC(G13) -> 19 | J13: =BIN2DEC(H13) -> 53 | K13: {=IF(I13=0,"",INDEX(Constants!$L:$L,Worksheet!I13))} -> S | L13: {=IF(J13=0,"",INDEX(Constants!$L:$L,Worksheet!J13))} -> 0 | M13: =_xlfn.CONCAT(K13,L13) -> S0
C14: =IF(ISBLANK(A14),0, _xlfn.XMATCH(A14,Constants!B:B)-1) -> 0 | D14: =DEC2BIN(C14,5) -> 00000 | E14: =_xlfn.CONCAT(IF(B14>=0,"0","1"),DEC2BIN(B14,6)) -> 0000000 | F14: =_xlfn.CONCAT(D14,E14) -> 000000000000 | G14: =LEFT(F14,6) -> 000000 | H14: =RIGHT(F14,6) -> 000000 | I14: =BIN2DEC(G14) -> 0 | J14: =BIN2DEC(H14) -> 0 | K14: {=IF(I14=0,"",INDEX(Constants!$L:$L,Worksheet!I14))} | L14: {=IF(J14=0,"",INDEX(Constants!$L:$L,Worksheet!J14))} | M14: =_xlfn.CONCAT(K14,L14)
C15: =IF(ISBLANK(A15),0, _xlfn.XMATCH(A15,Constants!B:B)-1) -> 0 | D15: =DEC2BIN(C15,5) -> 00000 | E15: =_xlfn.CONCAT(IF(B15>=0,"0","1"),DEC2BIN(B15,6)) -> 0000000 | F15: =_xlfn.CONCAT(D15,E15) -> 000000000000 | G15: =LEFT(F15,6) -> 000000 | H15: =RIGHT(F15,6) -> 000000 | I15: =BIN2DEC(G15) -> 0 | J15: =BIN2DEC(H15) -> 0 | K15: {=IF(I15=0,"",INDEX(Constants!$L:$L,Worksheet!I15))} | L15: {=IF(J15=0,"",INDEX(Constants!$L:$L,Worksheet!J15))} | M15: =_xlfn.CONCAT(K15,L15)
C16: =IF(ISBLANK(A16),0, _xlfn.XMATCH(A16,Constants!B:B)-1) -> 0 | D16: =DEC2BIN(C16,5) -> 00000 | E16: =_xlfn.CONCAT(IF(B16>=0,"0","1"),DEC2BIN(B16,6)) -> 0000000 | F16: =_xlfn.CONCAT(D16,E16) -> 000000000000 | G16: =LEFT(F16,6) -> 000000 | H16: =RIGHT(F16,6) -> 000000 | I16: =BIN2DEC(G16) -> 0 | J16: =BIN2DEC(H16) -> 0 | K16: {=IF(I16=0,"",INDEX(Constants!$L:$L,Worksheet!I16))} | L16: {=IF(J16=0,"",INDEX(Constants!$L:$L,Worksheet!J16))} | M16: =_xlfn.CONCAT(K16,L16)
C17: =IF(ISBLANK(A17),0, _xlfn.XMATCH(A17,Constants!B:B)-1) -> 0 | D17: =DEC2BIN(C17,5) -> 00000 | E17: =_xlfn.CONCAT(IF(B17>=0,"0","1"),DEC2BIN(B17,6)) -> 0000000 | F17: =_xlfn.CONCAT(D17,E17) -> 000000000000 | G17: =LEFT(F17,6) -> 000000 | H17: =RIGHT(F17,6) -> 000000 | I17: =BIN2DEC(G17) -> 0 | J17: =BIN2DEC(H17) -> 0 | K17: {=IF(I17=0,"",INDEX(Constants!$L:$L,Worksheet!I17))} | L17: {=IF(J17=0,"",INDEX(Constants!$L:$L,Worksheet!J17))} | M17: =_xlfn.CONCAT(K17,L17)
C18: =IF(ISBLANK(A18),0, _xlfn.XMATCH(A18,Constants!B:B)-1) -> 0 | D18: =DEC2BIN(C18,5) -> 00000 | E18: =_xlfn.CONCAT(IF(B18>=0,"0","1"),DEC2BIN(B18,6)) -> 0000000 | F18: =_xlfn.CONCAT(D18,E18) -> 000000000000 | G18: =LEFT(F18,6) -> 000000 | H18: =RIGHT(F18,6) -> 000000 | I18: =BIN2DEC(G18) -> 0 | J18: =BIN2DEC(H18) -> 0 | K18: {=IF(I18=0,"",INDEX(Constants!$L:$L,Worksheet!I18))} | L18: {=IF(J18=0,"",INDEX(Constants!$L:$L,Worksheet!J18))} | M18: =_xlfn.CONCAT(K18,L18)
C19: =IF(ISBLANK(A19),0, _xlfn.XMATCH(A19,Constants!B:B)-1) -> 0 | D19: =DEC2BIN(C19,5) -> 00000 | E19: =_xlfn.CONCAT(IF(B19>=0,"0","1"),DEC2BIN(B19,6)) -> 0000000 | F19: =_xlfn.CONCAT(D19,E19) -> 000000000000 | G19: =LEFT(F19,6) -> 000000 | H19: =RIGHT(F19,6) -> 000000 | I19: =BIN2DEC(G19) -> 0 | J19: =BIN2DEC(H19) -> 0 | K19: {=IF(I19=0,"",INDEX(Constants!$L:$L,Worksheet!I19))} | L19: {=IF(J19=0,"",INDEX(Constants!$L:$L,Worksheet!J19))} | M19: =_xlfn.CONCAT(K19,L19)
C20: =IF(ISBLANK(A20),0, _xlfn.XMATCH(A20,Constants!B:B)-1) -> 0 | D20: =DEC2BIN(C20,5) -> 00000 | E20: =_xlfn.CONCAT(IF(B20>=0,"0","1"),DEC2BIN(B20,6)) -> 0000000 | F20: =_xlfn.CONCAT(D20,E20) -> 000000000000 | G20: =LEFT(F20,6) -> 000000 | H20: =RIGHT(F20,6) -> 000000 | I20: =BIN2DEC(G20) -> 0 | J20: =BIN2DEC(H20) -> 0 | K20: {=IF(I20=0,"",INDEX(Constants!$L:$L,Worksheet!I20))} | L20: {=IF(J20=0,"",INDEX(Constants!$L:$L,Worksheet!J20))} | M20: =_xlfn.CONCAT(K20,L20)
M21: =_xlfn.CONCAT(K21,L21)
M22: =_xlfn.CONCAT(K22,L22)
M23: =_xlfn.CONCAT(K23,L23)
M24: =_xlfn.CONCAT(K24,L24)

Sheet Abilities
A3: Name | B3: Magic Type | C3: Speed | D3: Trigger | E3: Cost | F3: X | G3: Requirement | H3: X | I3: Effect
A4: Disguise Young | B4: Transform | D4: Battlecry | I4: Transform a creature into a creature type.
A5: Hide Young | B5: Illusion | D5: Greeting | I5: Give arriving creature Ward 3.
A6: Birth | B6: Transform | D6: Battlecry | I6: Give me +2 in a terrain mod.
A7: Feed | B7: Buff | D7: Attended | G7: Home | I7: Give me +2.
A8: Eyes Peeled | B8: Divination | D8: Battlecry | I8: Select a creature type.
A9: Hoof Stomp | B9: Communication | D9: Ambush | G9: is the triggering creature the selected creature type? | I9: Let a friendly creature retreat.
A10: Light Tail | B10: Illusion | G10: Once, Social X | H10: 5 | I10: Move all friendly creatures to the travel zone.
A11: Poison Moss | B11: Life | D11: Retaliate | I11: Deal 5 damage to attacking creature.
A12: Intercept | B12: Motion | D12: Intercept | I12: Change the target of the triggering ability to me.
A13: Scout | B13: Travel | D13: Dusk | I13: Move me to the Travel Zone.
A14: Deer Call | B14: Communication | D14: Dawn | I14: Deploy a friendly creature.
A15: Rack Attack | B15: Abjuration | D15: Battlecry | I15: Give a creature 3 Shields. Deal 5 damage to a creature.
A16: Reality Bend | B16: Life, Transform | C16: Slow | G16: Once | I16: Scout 3. Remove all terrains from the landmark. Give the landmark the terrains of the scouted biome.
A17: Antler Stab | B17: Attack | C17: Slow | E17: Rest X | F17: 1 | I17: Remove a terrain mod from a creature.
A18: Wasting | B18: Attack | D18: Battlecry | I18: Deal 1 damage to me.
A19: Perseverance | B19: Life | D19: Deathrattle | I19: Give me +2 in a terrain mod. Give me +2.
A20: Flame Spit | B20: Evocation | G20: Symbiotic | I20: Deal 5 damage to a creature.
A21: Cinder Roots | B21: Life | D21: When another creature takes damage, | I21: Give me +1.
A22: Indigenous | B22: Travel | C22: Super Fast | D22: Dawn | G22: Home | I22: Play this creature without triggering on-arrival.
A23: Glow | B23: Illusion, Evocation | D23: Greeting | I23: Give a creature an effect: "When I take damage, the damage is increased by 2, then remove this effect."
A24: Obsidian Feet | B24: Motion | D24: Retaliate | I24: Let me retreat.
A25: Flash Fire | B25: Evocation | E25: Exhaust X | F25: 1 | G25: Home | I25: Deal 2 damage to all non-Fire creatures. If at least 6 damage was dealt, give me +2.
A26: Homebound | B26: Travel | G26: Am I not at a home landmark? | I26: Remove my base power.
A27: Sunbathe | B27: Abjuration, Life | D27: Retaliate | G27: Is the attacking creature Fire? | I27: Give me +2.
A28: Acclimate Volcano | D28: Deathrattle | I28: Give a creature +2 in the Volcano terrain mod.
A29: Fire Breath | C29: Slow | G29: Once | I29: Deal 15 damage to all creatures of a creature type.
A30: Consume Flesh | E30: Rest X | F30: 1 | I30: Deal 1 damage to a creature. Give me +1.
A31: Consume Land | G31: Powerful X | H31: 10 | I31: Give the landmark the Volcano or Wasteland terrain.
A32: Armor Up | B32: Abjuration | D32: Deathrattle | I32: Give a creature 2 armor, briefly.
A33: Obsidian Armor | B33: Abjuration | D33: Retaliate | I33: Give me 4 armor, briefly.
A34: Obsidian Ball | B34: Motion | D34: Intercept | I34: Change the target of the triggering ability to me.
A35: Flamebow | B35: Evocation | E35: Exhaust X | F35: 2 | I35: Give all other Fire creatures +4.
A36: Ashes | B36: Life, Evocation | D36: Deathrattle | I36: Give me +4.
A37: Shady Deal | B37: Attack, Motion | E37: Land X | F37: 1 | I37: Deal 1 damage to another creature. Give selected creature 3 Shields.
A38: Howl Call | B38: Communication | D38: Battlecry | I38: Deploy a friendly creature.
A39: Swarm | B39: Buff | D39: Greeting | G39: Symbiotic | I39: Give me +1.
A40: Poison Bite | B40: Attack | D40: Deathrattle | I40: Deal 1 damage to a creature.
A41: Gather the Herd | B41: Travel | C41: Slow | D41: Dusk | G41: Social X | H41: 20 | I41: We win the game.

Sheet Constants
A1: Accipitrid | B1: Cloud | D1: Abjuration | E1: Super Fast | F1: Ambush | G1: Exhaust X | H1: Home | J1: Indigenous | L1: A
A2: Canid | B2: Desert | D2: Attack | E2: Fast | F2: Attended | G2: Land X | H2: Once | L2: B
A3: Cervid | B3: Forest | D3: Buff | E3: Normal | F3: Battlecry | G3: Rest X | H3: Powerful X | L3: C
A4: Chiropteran | B4: Jungle | D4: Communication | E4: Slow | F4: Dawn | H4: Social X | L4: D
A5: Culicid | B5: Lake | D5: Divination | E5: Super Slow | F5: Deathrattle | H5: Symbiotic | L5: E
A6: Draconid | B6: Mountain | D6: Evocation | F6: Dusk | L6: F
A7: Elementid | B7: Ocean | D7: Illusion | F7: Greeting | H7: Am I not at a home landmark? | L7: G
A8: Equine | B8: Plain | D8: Life | F8: Intercept | H8: Is the triggering creature the selected creature type? | L8: H
A9: Fire | B9: Swamp | D9: Motion | F9: Retaliate | H9: Is the attacking creature Fire? | L9: I
A10: Iguanid | B10: Tundra | D10: Transform | F10: Revenge | L10: J
A11: Lampyrid | B11: Volcano | D11: Travel | H11: Once, Social X | L11: K
A12: Light | B12: Wasteland | F12: When another creature takes damage, | L12: L
A13: Lumbricid | D13: Abjuration, Life | L13: M
A14: Phoenicopterid | D14: Attack, Motion | L14: N
A15: Plant | D15: Illusion, Evocation | L15: O
A16: Poison | D16: Life, Evocation | L16: P
A17: Polyporiceae | D17: Life, Transform | L17: Q
A18: Procyonid | L18: R
A19: Ramphastid | L19: S
A20: Rock | L20: T
A21: Scarabaeid | L21: U
A22: Stone | L22: V
A23: Theraphosid | L23: W
A24: Undead | L24: X
L25: Y
A26: Ramphastid, Fire | L26: Z
A27: Phoenicopterid, Stone | L27: a
A28: Cervid, Chiropteran | L28: b
A29: Cervid, Theraphosid | L29: c
A30: Cervid, Fire, Elementid | L30: d
A31: Cervid, Plant | L31: e
A32: Cervid, Plant, Light | L32: f
A33: Cervid, Plant, Poison | L33: g
A34: Cervid, Poison, Undead | L34: h
A35: Culicid, Poison | L35: i
A36: Draconid, Fire, Stone | L36: j
A37: Equid, Accipitrid, Fire | L37: k
... A44: Scarabaeid, Stone, Elementid | L44: r
L45: s
L46: t
...
